Workbook

Sheet Ciclo
A1: cod ciclo | B1: Nome | C1: tempo total | D1: tempo total decimal
A2: 1 | B2: Ciclo Faculdade | C2: 0.41634259 | D2: 9.9923

Sheet uniao ciclo atividade
A1: cod atividade | B1: cod ciclo | C1: % do tempo total | D1: tempo a fazer decimal | E1: tempo a fazer | F1: gp
A2: 1 | B2: 1 | C2: 14 | D2: =Ciclo!$D$2 * (C2/100) -> 1.398922 | E2: =Ciclo!$C$2 * (C2/100) -> 0.058287963 | F2: faculdade e TI
A3: 2 | B3: 1 | C3: 17 | D3: =Ciclo!$D$2 * (C3/100) -> 1.698691 | E3: =Ciclo!$C$2 * (C3/100) -> 0.070778241 | F3: faculdade e TI
A4: 3 | B4: 1 | C4: 13 | D4: =Ciclo!$D$2 * (C4/100) -> 1.298999 | E4: =Ciclo!$C$2 * (C4/100) -> 0.054124537 | F4: faculdade e TI
A5: 4 | B5: 1 | C5: 10 | D5: =Ciclo!$D$2 * (C5/100) -> 0.99923 | E5: =Ciclo!$C$2 * (C5/100) -> 0.041634259 | F5: vestibulares e concursos públicos
A6: 5 | B6: 1 | C6: 8 | D6: =Ciclo!$D$2 * (C6/100) -> 0.799384 | E6: =Ciclo!$C$2 * (C6/100) -> 0.033307407 | F6: vestibulares e concursos públicos
A7: 6 | B7: 1 | C7: 7 | D7: =Ciclo!$D$2 * (C7/100) -> 0.699461 | E7: =Ciclo!$C$2 * (C7/100) -> 0.029143981 | F7: vestibulares e concursos públicos
A8: 7 | B8: 1 | C8: 6 | D8: =Ciclo!$D$2 * (C8/100) -> 0.599538 | E8: =Ciclo!$C$2 * (C8/100) -> 0.024980556 | F8: vestibulares e concursos públicos
A9: 8 | B9: 1 | C9: 6 | D9: =Ciclo!$D$2 * (C9/100) -> 0.599538 | E9: =Ciclo!$C$2 * (C9/100) -> 0.024980556 | F9: vestibulares e concursos públicos
A10: 9 | B10: 1 | C10: 5 | D10: =Ciclo!$D$2 * (C10/100) -> 0.499615 | E10: =Ciclo!$C$2 * (C10/100) -> 0.02081713 | F10: hobbies
A11: 10 | B11: 1 | C11: 5 | D11: =Ciclo!$D$2 * (C11/100) -> 0.499615 | E11: =Ciclo!$C$2 * (C11/100) -> 0.02081713 | F11: hobbies
A12: 11 | B12: 1 | C12: 5 | D12: =Ciclo!$D$2 * (C12/100) -> 0.499615 | E12: =Ciclo!$C$2 * (C12/100) -> 0.02081713 | F12: hobbies
A13: 12 | B13: 1 | C13: 4 | D13: =Ciclo!$D$2 * (C13/100) -> 0.399692 | E13: =Ciclo!$C$2 * (C13/100) -> 0.016653704 | F13: hobbies

Sheet RegistroTodos (2)
A1: cod cadastro | B1: cod registro | C1: inicio | D1: fim | E1: data | F1: nome atividade | G1: tempo a fazer | H1: tempo a fazer decimal | I1: cod reg anterior | J1: cod reg andiantado
A2: 5 | B2: 1 | C2: 0.28490741 | D2: 0.36403935 | E2: 45835 | F2: projeto tk | G2: 0.10753472 | H2: 2.581
A3: 2 | B3: 2 | C3: 0.66423611 | D3: 0.70086806 | E3: 45835 | F3: Estudos logica e programação | G3: 0.15586806 | H3: 3.741
A4: 6 | B4: 3 | C4: 0.73655093 | D4: 0.75271991 | E4: 45835 | F4: Estudos violão | G4: 0.20549769 | H4: 4.932
A5: 1 | B5: 4 | C5: 0.54131944 | D5: 0.65532407 | E5: 45839 | F5: Estudos Banco de dados | G5: 0.07849537 | H5: 1.884
A6: 3 | B6: 5 | C6: 0.75641204 | D6: 0.80099537 | E6: 45839 | F6: Estudos Lingua portuguesa | G6: 0.14208333 | H6: 3.41
A7: 5 | B7: 6 | C7: 0.88543981 | D7: 0.90958333 | E7: 45839 | F7: projeto tk | G7: 0.083391204 | H7: 2.0014 | I7: 1
A8: 5 | B8: 7 | C8: 0.39109954 | D8: 0.41863426 | E8: 45840 | F8: Projeto tk | G8: 0.055856481 | H8: 1.3406 | I8: 6
A9: 4 | B9: 8 | C9: 0.77796296 | D9: 0.81263889 | E9: 45841 | F9: Estudos Matemática | G9: 0.15199074 | H9: 3.648
A10: 4 | B10: 9 | C10: 0.50875 | D10: 0.54832176 | E10: 45845 | F10: Estudos Matemática | G10: 0.11241898 | H10: 2.69806 | I10: 8
A11: 3 | B11: 10 | C11: 0.52506944 | D11: 0.54131944 | E11: 45855 | F11: Estudos Lingua portuguesa | G11: 0.12583333 | H11: 3.02 | I11: 5
A12: 3 | B12: 11 | C12: 0.83987269 | D12: 0.87304398 | E12: 45859 | F12: Estudos Lingua portuguesa | G12: 0.092662037 | H12: 2.224 | I12: 10
A13: 1 | B13: 12 | C13: 0.48695602 | D13: 0.52262731 | E13: 45860 | F13: Estudos Banco de dados | G13: 0.042824074 | H13: 1.028 | I13: 4
A14: 5 | B14: 13 | C14: 0.82975694 | D14: 0.88561343 | E14: 45860 | F14: projeto tk | G14: 0 | H14: 0 | I14: 7
A15: 2 | B15: 14 | C15: 0.48561343 | D15: 0.52121528 | E15: 45861 | F15: Estudos logica e programação | G15: 0.1202662 | H15: 2.8864 | I15: 2
A16: 2 | B16: 15 | C16: 0.45508102 | D16: 0.50746528 | E16: 45862 | F16: Estudos logica e programação | G16: 0.067881944 | H16: 1.6292 | I16: 14
A17: 4 | B17: 16 | C17: 0.47497685 | D17: 0.50038194 | E17: 45863 | F17: Estudos Matemática | G17: 0.087013889 | H17: 2.0884 | I17: 9
A18: 1 | B18: 17 | C18: 0.81579861 | D18: 0.85862269 | E18: 45867 | F18: Estudos Banco de dados | G18: 0 | H18: 0 | I18: 12
A19: 3 | B19: 18 | C19: 0.76672454 | D19: 0.81969907 | E19: 45872 | F19: Estudos Lingua portuguesa | G19: 0.0396875 | H19: 0.9525 | I19: 11
A20: 4 | B20: 19 | C20: 0.62475694 | D20: 0.66825231 | E20: 45873 | F20: Estudos Matemática | G20: 0.043518519 | H20: 1.0445 | I20: 16
A21: 2 | B21: 20 | C21: 0.50400463 | D21: 0.55009259 | E21: 45874 | F21: Estudos logica e programação | G21: 0.021793981 | H21: 0.52306 | I21: 15
... A28: 6 | B28: 27 | C28: 0.59740741 | D28: 0.68738426 | E28: 45878 | F28: Estudos violão | G28: 0 | H28: 0 | I28: 26
A29: 9 | B29: 28 | C29: 0.51150463 | D29: 0.55469907 | E29: 45882 | F29: projeto TK | G29: 0.0098842593 | H29: 0.2373
A30: 7 | B30: 29 | C30: 0.533125 | D30: 0.60097222 | E30: 45883 | F30: Banco de dados | G30: 0 | H30: 0
A31: 9 | B31: 30 | C31: 0.54056713 | D31: 0.614375 | E31: 45884 | F31: projeto TK | G31: 0 | H31: 0 | I31: 28
A32: 8 | B32: 31 | C32: 0.57190972 | D32: 0.60717593 | E32: 45887 | F32: logica e programação | G32: 0.034143519 | H32: 0.8195
A33: 8 | B33: 32 | C33: 0.49019676 | D33: 0.53469907 | E33: 45888 | F33: logica e programação | G33: 0 | H33: 0 | I33: 31
A34: 10 | B34: 33 | C34: 0.63305556 | D34: 0.6750463 | E34: 45888 | F34: Lingua portuguesa | G34: 0 | H34: 0
A35: 11 | B35: 34 | C35: 0.3483912 | D35: 0.38611111 | E35: 45889 | F35: história | G35: 0 | H35: 0
A36: 18 | B36: 35 | C36: 0.40480324 | D36: 0.42247685 | E36: 45889 | F36: violao | G36: 0 | H36: 0
A37: 12 | B37: 36 | C37: 0.46976852 | D37: 0.4993287 | E37: 45890 | F37: quimica | G37: 0 | H37: 0
A38: 13 | B38: 37 | C38: 0.50318287 | D38: 0.52796296 | E38: 45890 | F38: Matemática | G38: 0 | H38: 0
A39: 14 | B39: 38 | C39: 0.51740741 | D39: 0.54263889 | E39: 45891 | F39: geografia | G39: 0 | H39: 0
A40: 16 | B40: 39 | C40: 0.40100694 | D40: 0.42210648 | E40: 45892 | F40: crime e castigo | G40: 0 | H40: 0
A41: 17 | B41: 40 | C41: 0.42346065 | D41: 0.44387731 | E41: 45892 | F41: escrita | G41: 0 | H41: 0
A42: 15 | B42: 41 | C42: 0.85283565 | D42: 0.8787037 | E42: 45892 | F42: a vida intelectual sertillanges | G42: 0 | H42: 0
A43: 19 | B43: 42 | C43: 0.59028935 | D43: 0.60097222 | E43: 45883 | F43: Banco de dados | G43: 0.047604167 | H43: 1.1425 | J43: 29
A44: 21 | B44: 43 | C44: 0.55045139 | D44: 0.614375 | E44: 45884 | F44: projeto TK | G44: 0 | H44: 0 | J44: 30
A45: 20 | B45: 44 | C45: 0.52434028 | D45: 0.53469907 | E45: 45888 | F45: logica e programação | G45: 0.060416667 | H45: 1.45 | J45: 32
A46: 22 | B46: 45 | C46: 0.67388889 | D46: 0.6750463 | E46: 45888 | F46: Lingua portuguesa | G46: 0.040474537 | H46: 0.9714 | J46: 33
...

Sheet RegistroTodos

Sheet sessao
A1: cod cadastro | B1: % do tempo total | C1: tempo total atv decimal | D1: tempo total atv | E1: tempo total decimal | F1: tempo total | G1: tempo a fazer decimal | H1: tempo a fazer | I1: nome sessao | J1: gp | K1: cod atv | L1: cod ciclo | M1: nome atv | N1: nome ciclo | O1: acrescimo decimal | P1: ultimo registro
A2: 1 | B2: 16.5 | C2: =E2 * (B2/100) -> 4.62 | D2: =F2*(B2/100) -> 0.1925 | E2: 28 | F2: 1.1666667 | G2: 0 | H2: 0 | I2: sessao 1 | J2: prioridade 1 | K2: 1 | L2: 1 | M2: Estudos Banco de dados | N2: Ciclo Faculdade | O2: 0 | P2: 17
A3: 2 | B3: 16.5 | C3: =E3 * (B3/100) -> 4.62 | D3: =F3*(B3/100) -> 0.1925 | E3: 28 | F3: 1.1666667 | G3: 0 | H3: 0 | I3: sessao 1 | J3: prioridade 1 | K3: 2 | L3: 1 | M3: Estudos logica e programação | N3: Ciclo Faculdade | O3: 0 | P3: 24
A4: 3 | B4: 16 | C4: =E4 * (B4/100) -> 4.48 | D4: =F4*(B4/100) -> 0.18666667 | E4: 28 | F4: 1.1666667 | G4: 0 | H4: 0 | I4: sessao 1 | J4: prioridade 2 | K4: 4 | L4: 1 | M4: Estudos Lingua portuguesa | N4: Ciclo Faculdade | O4: 0 | P4: 23
A5: 4 | B5: 16 | C5: =E5 * (B5/100) -> 4.48 | D5: =F5*(B5/100) -> 0.18666667 | E5: 28 | F5: 1.1666667 | G5: 0 | H5: 0 | I5: sessao 1 | J5: prioridade 2 | K5: 7 | L5: 1 | M5: Estudos Matemática | N5: Ciclo Faculdade | O5: 0 | P5: 22
A6: 5 | B6: 16 | C6: =E6 * (B6/100) -> 4.48 | D6: =F6*(B6/100) -> 0.18666667 | E6: 28 | F6: 1.1666667 | G6: 0 | H6: 0 | I6: sessao 1 | J6: prioridade 2 | K6: 3 | L6: 1 | M6: projeto TK | N6: Ciclo Faculdade | O6: 0 | P6: 13
A7: 6 | B7: 19 | C7: =E7 * (B7/100) -> 5.32 | D7: =F7*(B7/100) -> 0.22166667 | E7: 28 | F7: 1.1666667 | G7: 0 | H7: 0 | I7: sessao 1 | J7: prioridade 3 | K7: 12 | L7: 1 | M7: Estudos violão | N7: Ciclo Faculdade | O7: 0 | P7: 27
A8: 7 | B8: 14 | C8: =E8 * (B8/100) -> 1.372 | D8: =F8*(B8/100) -> 0.057166667 | E8: 9.8 | F8: 0.40833333 | G8: 0 | H8: 0 | I8: sessao 2 | J8: faculdade e TI | K8: 1 | L8: 1 | M8: Banco de dados | N8: Ciclo Faculdade | O8: 0.2564
A9: 8 | B9: 17 | C9: =E9 * (B9/100) -> 1.666 | D9: =F9*(B9/100) -> 0.069416667 | E9: 9.8 | F9: 0.40833333 | G9: 0 | H9: 0 | I9: sessao 2 | J9: faculdade e TI | K9: 2 | L9: 1 | M9: logica e programação | N9: Ciclo Faculdade | O9: 0.2487
A10: 9 | B10: 13 | C10: =E10 * (B10/100) -> 1.274 | D10: =F10*(B10/100) -> 0.053083333 | E10: 9.8 | F10: 0.40833333 | G10: 0 | H10: 0 | I10: sessao 2 | J10: faculdade e TI | K10: 3 | L10: 1 | M10: projeto TK | N10: Ciclo Faculdade | O10: 1.5342
A11: 10 | B11: 10 | C11: =E11 * (B11/100) -> 0.98 | D11: =F11*(B11/100) -> 0.040833333 | E11: 9.8 | F11: 0.40833333 | G11: 0 | H11: 0 | I11: sessao 2 | J11: vestibulares e concursos públicos | K11: 4 | L11: 1 | M11: Lingua portuguesa | N11: Ciclo Faculdade | O11: 0.028
A12: 11 | B12: 8 | C12: =E12 * (B12/100) -> 0.784 | D12: =F12*(B12/100) -> 0.032666667 | E12: 9.8 | F12: 0.40833333 | G12: 0 | H12: 0 | I12: sessao 2 | J12: vestibulares e concursos públicos | K12: 5 | L12: 1 | M12: história | N12: Ciclo Faculdade | O12: 0.1214
A13: 12 | B13: 7 | C13: =E13 * (B13/100) -> 0.686 | D13: =F13*(B13/100) -> 0.028583333 | E13: 9.8 | F13: 0.40833333 | G13: 0 | H13: 0 | I13: sessao 2 | J13: vestibulares e concursos públicos | K13: 6 | L13: 1 | M13: quimica | N13: Ciclo Faculdade | O13: 0.0237
A14: 13 | B14: 6 | C14: =E14 * (B14/100) -> 0.588 | D14: =F14*(B14/100) -> 0.0245 | E14: 9.8 | F14: 0.40833333 | G14: 0 | H14: 0 | I14: sessao 2 | J14: vestibulares e concursos públicos | K14: 7 | L14: 1 | M14: Matemática | N14: Ciclo Faculdade | O14: 0.007
A15: 14 | B15: 6 | C15: =E15 * (B15/100) -> 0.588 | D15: =F15*(B15/100) -> 0.0245 | E15: 9.8 | F15: 0.40833333 | G15: 0 | H15: 0 | I15: sessao 2 | J15: vestibulares e concursos públicos | K15: 8 | L15: 1 | M15: geografia | N15: Ciclo Faculdade | O15: 0.018
A16: 15 | B16: 5 | C16: =E16 * (B16/100) -> 0.49 | D16: =F16*(B16/100) -> 0.020416667 | E16: 9.8 | F16: 0.40833333 | G16: 0 | H16: 0 | I16: sessao 2 | J16: hobbies | K16: 9 | L16: 1 | M16: a vida intelectual sertillanges | N16: Ciclo Faculdade | O16: 0.131
A17: 16 | B17: 5 | C17: =E17 * (B17/100) -> 0.49 | D17: =F17*(B17/100) -> 0.020416667 | E17: 9.8 | F17: 0.40833333 | G17: 0 | H17: 0 | I17: sessao 2 | J17: hobbies | K17: 10 | L17: 1 | M17: crime e castigo | N17: Ciclo Faculdade | O17: 0.0164
A18: 17 | B18: 5 | C18: =E18 * (B18/100) -> 0.49 | D18: =F18*(B18/100) -> 0.020416667 | E18: 9.8 | F18: 0.40833333 | G18: 0 | H18: 0 | I18: sessao 2 | J18: hobbies | K18: 11 | L18: 1 | M18: escrita | N18: Ciclo Faculdade | O18: 0.0323
A19: 18 | B19: 4 | C19: =E19 * (B19/100) -> 0.392 | D19: =F19*(B19/100) -> 0.016333333 | E19: 9.8 | F19: 0.40833333 | G19: 0 | H19: 0 | I19: sessao 2 | J19: hobbies | K19: 12 | L19: 1 | M19: violao | N19: Ciclo Faculdade
A20: 19 | B20: 14 | C20: =E20 * (B20/100) -> 1.398922 | D20: =F20*(B20/100) -> 0.058287963 | E20: 9.9923 | F20: 0.41634259 | I20: sessao 3 | J20: faculdade e TI | K20: 1 | L20: 1 | M20: Banco de dados | N20: Ciclo Faculdade | O20: =A20 -> 19
A21: 20 | B21: 17 | C21: =E21 * (B21/100) -> 1.698691 | D21: =F21*(B21/100) -> 0.070778241 | E21: 9.9923 | F21: 0.41634259 | I21: sessao 3 | J21: faculdade e TI | K21: 2 | L21: 1 | M21: logica e programação | N21: Ciclo Faculdade | O21: =A21 -> 20
A22: 21 | B22: 13 | C22: =E22 * (B22/100) -> 1.298999 | D22: =F22*(B22/100) -> 0.054124537 | E22: 9.9923 | F22: 0.41634259 | I22: sessao 3 | J22: faculdade e TI | K22: 3 | L22: 1 | M22: projeto TK | N22: Ciclo Faculdade | O22: =A22 -> 21
A23: 22 | B23: 10 | C23: =E23 * (B23/100) -> 0.99923 | D23: =F23*(B23/100) -> 0.041634259 | E23: 9.9923 | F23: 0.41634259 | I23: sessao 3 | J23: vestibulares e concursos públicos | K23: 4 | L23: 1 | M23: Lingua portuguesa | N23: Ciclo Faculdade | O23: =A23 -> 22
A24: 23 | B24: 8 | C24: =E24 * (B24/100) -> 0.799384 | D24: =F24*(B24/100) -> 0.033307407 | E24: 9.9923 | F24: 0.41634259 | I24: sessao 3 | J24: vestibulares e concursos públicos | K24: 5 | L24: 1 | M24: história | N24: Ciclo Faculdade | O24: =A24 -> 23
A25: 24 | B25: 7 | C25: =E25 * (B25/100) -> 0.699461 | D25: =F25*(B25/100) -> 0.029143981 | E25: 9.9923 | F25: 0.41634259 | I25: sessao 3 | J25: vestibulares e concursos públicos | K25: 6 | L25: 1 | M25: quimica | N25: Ciclo Faculdade | O25: =A25 -> 24
A26: 25 | B26: 6 | C26: =E26 * (B26/100) -> 0.599538 | D26: =F26*(B26/100) -> 0.024980556 | E26: 9.9923 | F26: 0.41634259 | I26: sessao 3 | J26: vestibulares e concursos públicos | K26: 7 | L26: 1 | M26: Matemática | N26: Ciclo Faculdade | O26: =A26 -> 25
A27: 26 | B27: 6 | C27: =E27 * (B27/100) -> 0.599538 | D27: =F27*(B27/100) -> 0.024980556 | E27: 9.9923 | F27: 0.41634259 | I27: sessao 3 | J27: vestibulares e concursos públicos | K27: 8 | L27: 1 | M27: geografia | N27: Ciclo Faculdade | O27: =A27 -> 26
A28: 27 | B28: 5 | C28: =E28 * (B28/100) -> 0.499615 | D28: =F28*(B28/100) -> 0.02081713 | E28: 9.9923 | F28: 0.41634259 | I28: sessao 3 | J28: hobbies | K28: 9 | L28: 1 | M28: a vida intelectual sertillanges | N28: Ciclo Faculdade | O28: =A28 -> 27
A29: 28 | B29: 5 | C29: =E29 * (B29/100) -> 0.499615 | D29: =F29*(B29/100) -> 0.02081713 | E29: 9.9923 | F29: 0.41634259 | I29: sessao 3 | J29: hobbies | K29: 10 | L29: 1 | M29: crime e castigo | N29: Ciclo Faculdade | O29: =A29 -> 28
A30: 29 | B30: 5 | C30: =E30 * (B30/100) -> 0.499615 | D30: =F30*(B30/100) -> 0.02081713 | E30: 9.9923 | F30: 0.41634259 | I30: sessao 3 | J30: hobbies | K30: 11 | L30: 1 | M30: escrita | N30: Ciclo Faculdade | O30: =A30 -> 29
A31: 30 | B31: 4 | C31: =E31 * (B31/100) -> 0.399692 | D31: =F31*(B31/100) -> 0.016653704 | E31: 9.9923 | F31: 0.41634259 | I31: sessao 3 | J31: hobbies | K31: 12 | L31: 1 | M31: violao | N31: Ciclo Faculdade | O31: =A31 -> 30

Sheet Atividade
A1: cod atividade | B1: Nome
A2: 1 | B2: Banco de dados
A3: 2 | B3: logica e programação
A4: 3 | B4: projeto TK
A5: 4 | B5: Lingua portuguesa
A6: 5 | B6: história
A7: 6 | B7: quimica
A8: 7 | B8: Matemática
A9: 8 | B9: geografia
A10: 9 | B10: a vida intelectual sertillanges
A11: 10 | B11: crime e castigo
A12: 11 | B12: escrita
A13: 12 | B13: violao
